Traceback (most recent call last):
  File "/home/msh9584/newbeans/manage.py", line 15, in <module>
    execute_from_command_line(sys.argv)
  File "/home/msh9584/venv/lib/python3.7/site-packages/django/core/management/__init__.py", line 381, in execute_from_command_line
    utility.execute()
  File "/home/msh9584/venv/lib/python3.7/site-packages/django/core/management/__init__.py", line 375, in execute
    self.fetch_command(subcommand).run_from_argv(self.argv)
  File "/home/msh9584/venv/lib/python3.7/site-packages/django/core/management/base.py", line 323, in run_from_argv
    self.execute(*args, **cmd_options)
  File "/home/msh9584/venv/lib/python3.7/site-packages/django/core/management/base.py", line 364, in execute
    output = self.handle(*args, **options)
  File "/home/msh9584/venv/lib/python3.7/site-packages/django_crontab/management/commands/crontab.py", line 29, in handle
    Crontab().run_job(options['jobhash'])
  File "/home/msh9584/venv/lib/python3.7/site-packages/django_crontab/crontab.py", line 126, in run_job
    job = self.__get_job_by_hash(job_hash)
  File "/home/msh9584/venv/lib/python3.7/site-packages/django_crontab/crontab.py", line 173, in __get_job_by_hash
    'Run "python manage.py crontab add" again to resolve this issue!' % job_hash
RuntimeError: No job with hash 2891f7080ecf56b6e8ecea4764da4cf9 found. It seems the crontab is out of sync with your settings.CRONJOBS. Run "python manage.py crontab add" again to resolve this issue!
Traceback (most recent call last):
  File "/home/msh9584/newbeans/manage.py", line 15, in <module>
    execute_from_command_line(sys.argv)
  File "/home/msh9584/venv/lib/python3.7/site-packages/django/core/management/__init__.py", line 381, in execute_from_command_line
    utility.execute()
  File "/home/msh9584/venv/lib/python3.7/site-packages/django/core/management/__init__.py", line 375, in execute
    self.fetch_command(subcommand).run_from_argv(self.argv)
  File "/home/msh9584/venv/lib/python3.7/site-packages/django/core/management/base.py", line 323, in run_from_argv
    self.execute(*args, **cmd_options)
  File "/home/msh9584/venv/lib/python3.7/site-packages/django/core/management/base.py", line 364, in execute
    output = self.handle(*args, **options)
  File "/home/msh9584/venv/lib/python3.7/site-packages/django_crontab/management/commands/crontab.py", line 29, in handle
    Crontab().run_job(options['jobhash'])
  File "/home/msh9584/venv/lib/python3.7/site-packages/django_crontab/crontab.py", line 126, in run_job
    job = self.__get_job_by_hash(job_hash)
  File "/home/msh9584/venv/lib/python3.7/site-packages/django_crontab/crontab.py", line 173, in __get_job_by_hash
    'Run "python manage.py crontab add" again to resolve this issue!' % job_hash
RuntimeError: No job with hash 5dfcac338e6113b1e3e9b95e6bd7040b found. It seems the crontab is out of sync with your settings.CRONJOBS. Run "python manage.py crontab add" again to resolve this issue!
Traceback (most recent call last):
  File "/home/msh9584/newbeans/manage.py", line 15, in <module>
    execute_from_command_line(sys.argv)
  File "/home/msh9584/venv/lib/python3.7/site-packages/django/core/management/__init__.py", line 381, in execute_from_command_line
    utility.execute()
  File "/home/msh9584/venv/lib/python3.7/site-packages/django/core/management/__init__.py", line 375, in execute
    self.fetch_command(subcommand).run_from_argv(self.argv)
  File "/home/msh9584/venv/lib/python3.7/site-packages/django/core/management/base.py", line 323, in run_from_argv
    self.execute(*args, **cmd_options)
  File "/home/msh9584/venv/lib/python3.7/site-packages/django/core/management/base.py", line 364, in execute
    output = self.handle(*args, **options)
  File "/home/msh9584/venv/lib/python3.7/site-packages/django_crontab/management/commands/crontab.py", line 29, in handle
    Crontab().run_job(options['jobhash'])
  File "/home/msh9584/venv/lib/python3.7/site-packages/django_crontab/crontab.py", line 126, in run_job
    job = self.__get_job_by_hash(job_hash)
  File "/home/msh9584/venv/lib/python3.7/site-packages/django_crontab/crontab.py", line 173, in __get_job_by_hash
    'Run "python manage.py crontab add" again to resolve this issue!' % job_hash
RuntimeError: No job with hash 701db0c88bf6f07f0d21904c298f96ac found. It seems the crontab is out of sync with your settings.CRONJOBS. Run "python manage.py crontab add" again to resolve this issue!
Traceback (most recent call last):
  File "/home/msh9584/newbeans/manage.py", line 15, in <module>
    execute_from_command_line(sys.argv)
  File "/home/msh9584/venv/lib/python3.7/site-packages/django/core/management/__init__.py", line 381, in execute_from_command_line
    utility.execute()
  File "/home/msh9584/venv/lib/python3.7/site-packages/django/core/management/__init__.py", line 375, in execute
    self.fetch_command(subcommand).run_from_argv(self.argv)
  File "/home/msh9584/venv/lib/python3.7/site-packages/django/core/management/base.py", line 323, in run_from_argv
    self.execute(*args, **cmd_options)
  File "/home/msh9584/venv/lib/python3.7/site-packages/django/core/management/base.py", line 364, in execute
    output = self.handle(*args, **options)
  File "/home/msh9584/venv/lib/python3.7/site-packages/django_crontab/management/commands/crontab.py", line 29, in handle
    Crontab().run_job(options['jobhash'])
  File "/home/msh9584/venv/lib/python3.7/site-packages/django_crontab/crontab.py", line 126, in run_job
    job = self.__get_job_by_hash(job_hash)
  File "/home/msh9584/venv/lib/python3.7/site-packages/django_crontab/crontab.py", line 173, in __get_job_by_hash
    'Run "python manage.py crontab add" again to resolve this issue!' % job_hash
RuntimeError: No job with hash 7550b8af1e92055e9781f2759f2bd101 found. It seems the crontab is out of sync with your settings.CRONJOBS. Run "python manage.py crontab add" again to resolve this issue!
Traceback (most recent call last):
  File "/home/msh9584/newbeans/manage.py", line 15, in <module>
    execute_from_command_line(sys.argv)
  File "/home/msh9584/venv/lib/python3.7/site-packages/django/core/management/__init__.py", line 381, in execute_from_command_line
    utility.execute()
  File "/home/msh9584/venv/lib/python3.7/site-packages/django/core/management/__init__.py", line 375, in execute
    self.fetch_command(subcommand).run_from_argv(self.argv)
  File "/home/msh9584/venv/lib/python3.7/site-packages/django/core/management/base.py", line 323, in run_from_argv
    self.execute(*args, **cmd_options)
  File "/home/msh9584/venv/lib/python3.7/site-packages/django/core/management/base.py", line 364, in execute
    output = self.handle(*args, **options)
  File "/home/msh9584/venv/lib/python3.7/site-packages/django_crontab/management/commands/crontab.py", line 29, in handle
    Crontab().run_job(options['jobhash'])
  File "/home/msh9584/venv/lib/python3.7/site-packages/django_crontab/crontab.py", line 126, in run_job
    job = self.__get_job_by_hash(job_hash)
  File "/home/msh9584/venv/lib/python3.7/site-packages/django_crontab/crontab.py", line 173, in __get_job_by_hash
    'Run "python manage.py crontab add" again to resolve this issue!' % job_hash
RuntimeError: No job with hash a0cc806f65afc5ebc91c079e46a28bad found. It seems the crontab is out of sync with your settings.CRONJOBS. Run "python manage.py crontab add" again to resolve this issue!
